Workbook
Name Aktualizace: TabulkaAktualizace[Aktualizace]
Name Aktualizace: TabulkaAktualizace[Aktualizace]
Name CIA: TabulkaCIA[CIA]
Name CIA: TabulkaCIA[CIA]
Name Dopad: TabulkaDopad[Dopad]
Name Dopad: TabulkaDopad[Dopad]
Name Kategorie: TabulkaKategorie[Kategorie]
Name Kategorie: TabulkaKategorie[Kategorie]
Name Oddělení: TabulkaOddělení[Oddělení]
Name Oddělení: TabulkaOddělení[Oddělení]
Name Přístup: TabulkaPřístup[Přístup]
Name Přístup: TabulkaPřístup[Přístup]
Name Riziko: TabulkaDopad[Riziko]
Name Riziko: TabulkaDopad[Riziko]
Name Síť: TabulkaSíť[Síť]
Name Síť: TabulkaSíť[Síť]
Name Stav: TabulkaStav[Stav]
Name Stav: TabulkaStav[Stav]
Name StavAktiva: TabulkaStavAktiva[StavAktiva]
Name StavAktiva: TabulkaStavAktiva[StavAktiva]
Name TypAktiva: TabulkaTypAktiva[Typ aktiva]
Name TypAktiva: TabulkaTypAktiva[Typ aktiva]
Name TypPoznámky: TabulkaPoznámka[TypPoznámky]
Name TypPoznámky: TabulkaPoznámka[TypPoznámky]
Name Zálohování: TabulkaZálohování[Zálohování]
Name Zálohování: TabulkaZálohování[Zálohování]

Sheet Asset Register
A1: Asset ID Jednoznačný identifikátor | B1: Název aktiva Srozumitelný název | C1: Typ aktiva IT / OT / IoT | D1: Kategorie Server, PLC, Sensor, Aplikace… | E1: Vlastník Role odpovědné osoby | F1: Oddělení IT / Provoz / Údržba | G1: Umístění Budova / rozvaděč / lokalita | H1: Stav aktiva Provozní | I1: Kritičnost Souhrn CIA, Nízká / Střední / Vysoká | J1: Dostupnost Nízká / Střední / Vysoká | K1: Integrita Nízká / Střední / Vysoká | L1: Důvěrnost Nízká / Střední / Vysoká | M1: Síť LAN / OT / Internet / Offline | N1: Přístup Lokální / Remote / VPN | O1: Zálohování Ano / Ne / N/A | P1: Aktualizace Automatické / Ruční / Není možné | Q1: Poslední revize Datum | R1: Vazba na službu / proces podporovaný aktivem | S1: Typ poznámky Riziko / výjimka / technický dluh / provozní omezení | T1: Poznámka Stručný popis
A2: DEV-01 | B2: Telemetrické jednotky typu A | C2: IoT | D2: Senzor | E2: System specialist | F2: IT | G2: Firma X, lokomotiva | H2: V provozu | I2: Vysoká | J2: Střední | K2: Vysoká | L2: Vysoká | M2: Internet | N2: Remote | O2: N/A | P2: Ruční | Q2: 46034 | R2: Sběr telemetrických dat | S2: Technický dluh | T2: Chybí privátní APN/VPN pro management přístup k jednotkám.
A3: FW-01 | B3: Firmware LOKO01 pro telemetrické jednotky typu A | C3: IT | D3: Software/firmware | E3: Lead Developer | F3: IT | G3: Firma X, lokomotiva | H3: V provozu | I3: Vysoká | J3: Střední | K3: Vysoká | L3: Vysoká | M3: Offline | N3: Remote | O3: Ne | P3: Ruční | Q3: 46034 | R3: Sběr telemetrických dat | S3: Riziko | T3: Firmware neobsahuje digitální podpis
A4: NET-SIM-01 | B4: SIM karta pro konektivitu pro telemetrické jednotky typu A | C4: OT | D4: Síťové zařízení | E4: Network Administrator | F4: IT | G4: Mobilní - lokomotivy | H4: V provozu | I4: Vysoká | J4: Vysoká | K4: Střední | L4: Střední | M4: Internet | N4: Remote | O4: N/A | P4: Není možné | Q4: 46034 | R4: Sběr telemetrických dat | S4: Riziko | T4: vyjmutí/krádež SIM karty
A5: NET-HTTPS-01 | B5: HTTPS pro konektivitu pro telemetrické jednotky typu A | C5: IT | D5: Síťová služba | E5: Network Administrator | F5: IT | G5: Veřejný internet | H5: V provozu | I5: Střední | J5: Střední | K5: Střední | L5: Střední | M5: Internet | N5: Remote | O5: N/A | P5: Není možné | Q5: 46034 | R5: Sběr telemetrických dat | S5: Technický dluh | T5: Chybějící privátní APN/VPN. Data jsou vystavena ve veřejném internetu, což zvyšuje plochu pro útok.
A6: DAT-01 | B6: Data z telemetrických jednotek typu A | C6: IT | D6: Dataset / Data | E6: System specialist | F6: IT | G6: loko.flt.eu | H6: V provozu | I6: Vysoká | J6: Střední | K6: Vysoká | L6: Vysoká | M6: Internet | N6: Remote | O6: Ano | P6: Není možné | Q6: 46035 | R6: Sběr telemetrických dat | S6: Technický dluh | T6: Data jsou uložena na backendu gxtdm.eu. Pozn.: Nutno ověřit existenci a periodu záloh (RTO/RPO).
A7: API-01 | B7: Telemetry Data API (FLT) | C7: IT | D7: Aplikace | E7: Lead Developer | F7: IT | G7: loko.flt.eu/api/v1 | H7: V provozu | I7: Vysoká | J7: Vysoká | K7: Vysoká | L7: Vysoká | M7: Internet | N7: Remote | O7: N/A | P7: Není možné | Q7: 46035 | R7: Sběr telemetrických dat | S7: Technický dluh | T7: Absence moderních autentizačních mechanismů (např. mTLS nebo OAuth2). API využívá pouze statické heslo, což je v rozporu se standardy pro kritickou infrastrukturu.
A8: SYS-BACK-01 | B8: Backend infrastruktura | C8: IT | D8: Server | E8: Dodavatel | F8: Externí dodavatel | G8: Datacentrum dodavatele | H8: V provozu | I8: Vysoká | J8: Vysoká | K8: Vysoká | L8: Vysoká | M8: Internet | N8: VPN | O8: Ano | P8: Není možné | Q8: 46035 | R8: Sběr telemetrických dat | S8: Riziko | T8: Provoz zajištěn externě. Kritická závislost na finanční stabilitě a kybernetické bezpečnosti dodavatele (SLA).
A9: SYS-BACK-02 | B9: Záložní backend infrastruktura | C9: IT | D9: Server | E9: Dodavatel | F9: Externí dodavatel | G9: Datacentrum dodavatele | H9: V provozu | I9: Vysoká | J9: Vysoká | K9: Vysoká | L9: Vysoká | M9: Internet | N9: VPN | O9: Ano | P9: Není možné | Q9: 46035 | R9: Sběr telemetrických dat | S9: Riziko | T9: Horká záloha (Hot Standby). Zajišťuje vysokou dostupnost, ale nechrání před logickým smazáním dat (např. ransomware).
A10: NET-VPN-01 | B10: Správcovský přístup k backend inrastruktuře | C10: IT | D10: Síťová služba | E10: Dodavatel | F10: Externí dodavatel | G10: Datacentrum dodavatele | H10: V provozu | I10: Vysoká | J10: Střední | K10: Střední | L10: Vysoká | M10: Internet | N10: VPN | O10: N/A | P10: Automatické | Q10: 46035 | R10: Sběr telemetrických dat | S10: Technický dluh | T10: Chybí vícefaktorové ověření (MFA). Kompromitace jednoho notebooku správce znamená přístup k celé infrastruktuře.
A11: APP-WEB-01 | B11: Fleet Monitoring Web App | C11: IT | D11: Software / Firmware | E11: Product Manager | F11: IT | G11: fleet.flt.eu (veřejné rozhraní) | H11: V provozu | I11: Vysoká | J11: Vysoká | K11: Střední | L11: Vysoká | M11: Internet | N11: Remote | O11: Ano | P11: Automatické | Q11: 46036 | R11: Sběr telemetrických dat | S11: Riziko | T11: Veřejně dostupná webová aplikace vystavená internetu. Zvýšená plocha útoku (OWASP Top 10). Nutnost pravidelného bezpečnostního testování a řízení zranitelností.
A12: USR-DATA-01 | B12: Uživatelské účty a profily | C12: IT | D12: Dataset / Data | E12: System specialist | F12: IT | G12: Datacentrum dodavatele | H12: V provozu | I12: Vysoká | J12: Střední | K12: Vysoká | L12: Vysoká | M12: Internet | N12: Remote | O12: Ano | P12: Není možné | Q12: 46036 | R12: Sběr telemetrických dat | S12: Riziko | T12: Nedostatečná granularita nebo chybná konfigurace rolí. Chybí definovaná politika správy identit a rolí (IAM).
A13: POL-SEC-01 | B13: Bezpečnostní politika | C13: IT | D13: Politika / Governance | E13: IT manager | F13: IT | G13: Interní dokumentace | H13: V provozu | I13: Vysoká | J13: Střední | K13: Vysoká | L13: Střední | M13: Offline | N13: Lokální | O13: N/A | P13: Ruční | Q13: 46036 | R13: Governance kybernetické bezpečnosti | S13: Riziko | T13: Chybí formálně schválená bezpečnostní politika definující role, odpovědnosti a minimální bezpečnostní požadavky.
... A15: PROC-VULN-01 | B15: Vulnerability Management Process | C15: IT | D15: Proces | E15: IT manager | F15: IT | G15: Interní dokumentace | H15: V provozu | I15: Vysoká | J15: Vysoká | K15: Vysoká | L15: Střední | M15: Offline | N15: Lokální | O15: N/A | P15: Ruční | Q15: 46036 | R15: Řízení zranitelností | S15: Technický dluh | T15: Chybí systematický proces vyhledávání, hodnocení a odstraňování zranitelností v aplikacích, API a infrastruktuře.

Sheet Risk Register
A1: Risk ID | B1: Asset ID | C1: Název aktiva | D1: Vlastník rizika | E1: Název rizika | F1: Popis rizika | G1: Dopad | H1: Pravděpodobnost | I1: Úroveň rizika | J1: Priorita | K1: Stávající opatření | L1: Doporučené opatření | M1: Stav | N1: Datum revize
A2: RISK-DEV-01 | B2: DEV-01 | C2: =IFERROR(VLOOKUP(B2, 'Asset Register'!A:B, 2, FALSE), "") -> Telemetrické jednotky typu A | D2: Fleet manager | E2: Neautorizovaný přístup k nastavení jednotky | F2: Chybějící VPN umožňuje útočníkovi vzdáleně změnit nastavení jednotky, což znemožní odesílání správných provozních dat | G2: Vysoký | H2: Střední | I2: =IF(OR(G2="", H2=""), "", INDEX(_RiskMatrix!$B$2:$D$4, MATCH(G2, _RiskMatrix!$A$2:$A$4, 0), MATCH(H2, _RiskMatrix!$B$1:$D$1, 0) )) -> Vysoká | J2: =IF(I2="", "", I2) -> Vysoká | K2: Login ve formátu "příjmení", základní heslo | L2: Zavést privátní APN/VPN pro management přístup k jednotkám + politika silných hesel. | M2: Otevřené | N2: 46034
A3: RISK-DEV-02 | B3: DEV-01 | C3: =IFERROR(VLOOKUP(B3, 'Asset Register'!A:B, 2, FALSE), "") -> Telemetrické jednotky typu A | D3: Fleet manager | E3: Fyzické zničení nebo odcizení jednotky | F3: Pachatel vnikne do lokomotivy a jednotku demontuje nebo úmyslně poškodí | G3: Střední | H3: Nízká | I3: =IF(OR(G3="", H3=""), "", INDEX(_RiskMatrix!$B$2:$D$4, MATCH(G3, _RiskMatrix!$A$2:$A$4, 0), MATCH(H3, _RiskMatrix!$B$1:$D$1, 0) )) -> Nízká | J3: =IF(I3="", "", I3) -> Nízká | K3: organizační/fyzické kontroly | L3: Alarm při ztrátě napájení | M3: Akceptované | N3: 46034
A4: RISK-DEV-03 | B4: DEV-01 | C4: =IFERROR(VLOOKUP(B4, 'Asset Register'!A:B, 2, FALSE), "") -> Telemetrické jednotky typu A | D4: Fleet manager | E4: Nedostupnost telemetrických dat (Offline stav) | F4: Selhání konektivity (SIM karta) nebo nekompatibilita FW zařízení 3. stran způsobí výpadek dat, což vede k porušení SLA (reakce do 3 dnů). | G4: Střední | H4: Střední | I4: =IF(OR(G4="", H4=""), "", INDEX(_RiskMatrix!$B$2:$D$4, MATCH(G4, _RiskMatrix!$A$2:$A$4, 0), MATCH(H4, _RiskMatrix!$B$1:$D$1, 0) )) -> Střední | J4: =IF(I4="", "", I4) -> Střední | K4: pravidelný vzdálený monitoring, funkční kontroly v provozu | L4: Integrované čipové SIM | M4: Řeší se | N4: 46034
A5: RISK-FW-01 | B5: FW-01 | C5: =IFERROR(VLOOKUP(B5, 'Asset Register'!A:B, 2, FALSE), "") -> Firmware LOKO01 pro telemetrické jednotky typu A | D5: Fleet manager | E5: Podvržení firmwaru (Missing Code Signing) | F5: Absence digitálního podpisu umožňuje nahrát neautorizovaný software, což může vést k úplnému převzetí kontroly nad jednotkou. | G5: Vysoký | H5: Střední | I5: =IF(OR(G5="", H5=""), "", INDEX(_RiskMatrix!$B$2:$D$4, MATCH(G5, _RiskMatrix!$A$2:$A$4, 0), MATCH(H5, _RiskMatrix!$B$1:$D$1, 0) )) -> Vysoká | J5: =IF(I5="", "", I5) -> Vysoká | K5: Žádná (jednotka přijme jakýkoliv binární soubor). | L5: Implementace Digitálního podepisování (Code Signing). Vývojář podepíše FW soukromým klíčem a jednotka pomocí veřejného klíče ověří integritu před instalací. | M5: Řeší se | N5: 46034
A6: RISK-NET-01 | B6: NET-SIM-01 | C6: =IFERROR(VLOOKUP(B6, 'Asset Register'!A:B, 2, FALSE), "") -> SIM karta pro konektivitu pro telemetrické jednotky typu A | D6: Fleet manager | E6: Fyzické zneužití / krádež SIM karty | F6: Neautorizovaná osoba vyjme SIM z jednotky. Následkem je offline stav jednotky (ztráta dat) a riziko finanční škody (zneužití datového tarifu v jiném zařízení). | G6: Střední | H6: Nízká | I6: =IF(OR(G6="", H6=""), "", INDEX(_RiskMatrix!$B$2:$D$4, MATCH(G6, _RiskMatrix!$A$2:$A$4, 0), MATCH(H6, _RiskMatrix!$B$1:$D$1, 0) )) -> Nízká | J6: =IF(I6="", "", I6) -> Nízká | K6: provozní opatření fyzické bezpečnosti zákazníka, omezení dat | L6: Žádné | M6: Akceptované | N6: 46034
A7: RISK-NET-02 | B7: NET-HTTPS-01 | C7: =IFERROR(VLOOKUP(B7, 'Asset Register'!A:B, 2, FALSE), "") -> HTTPS pro konektivitu pro telemetrické jednotky typu A | D7: Fleet manager | E7: Expirace/chyba SSL certifikátu | F7: Vypršení platnosti certifikátu na straně serveru způsobí, že se jednotky přestanou připojovat. | G7: Střední | H7: Nízká | I7: =IF(OR(G7="", H7=""), "", INDEX(_RiskMatrix!$B$2:$D$4, MATCH(G7, _RiskMatrix!$A$2:$A$4, 0), MATCH(H7, _RiskMatrix!$B$1:$D$1, 0) )) -> Nízká | J7: =IF(I7="", "", I7) -> Nízká | K7: Šifrování přenosu pomocí TLS 1.2+ a ověřování identity serveru pomocí certifikátu. | L7: Automatizovaný monitoring a alerting: Nasazení nástroje, který hlídá platnost certifikátů a pošle upozornění (např. 30 dní před vypršením) na IT dohled. | M7: Uzavřené | N7: 46034
A8: RISK-DAT-01 | B8: DAT-01 | C8: =IFERROR(VLOOKUP(B8, 'Asset Register'!A:B, 2, FALSE), "") -> Data z telemetrických jednotek typu A | D8: Fleet manager | E8: Nedostatečná strategie obnovy dat (Backup & Recovery) | F8: Absence definovaných parametrů RTO/RPO a neověřená funkčnost záloh může vést k trvalé ztrátě historie telemetrie při havárii serveru. | G8: Vysoký | H8: Střední | I8: =IF(OR(G8="", H8=""), "", INDEX(_RiskMatrix!$B$2:$D$4, MATCH(G8, _RiskMatrix!$A$2:$A$4, 0), MATCH(H8, _RiskMatrix!$B$1:$D$1, 0) )) -> Vysoká | J8: =IF(I8="", "", I8) -> Vysoká | K8: Jednotka disponuje interní pamětí pro uložení dat po dobu 14 dnů v případě nedostupnosti sítě nebo backendu. | L8: Smluvně zakotvit (SLA) s poskytovatelem gxtdm.eu povinnost zálohování a definovat v nich právě RTO a RPO. | M8: Řeší se | N8: 46035
A9: RISK-API-01 | B9: API-01 | C9: =IFERROR(VLOOKUP(B9, 'Asset Register'!A:B, 2, FALSE), "") -> Telemetry Data API (FLT) | D9: Fleet manager | E9: Expozice klíčů (API Key Leak) | F9: Pokud útočník získá API klíč (třeba z firmwaru nebo od bývalého zaměstnance), může do systému sypat falešná data nebo všechna data ukrást. | G9: Vysoký | H9: Střední | I9: =IF(OR(G9="", H9=""), "", INDEX(_RiskMatrix!$B$2:$D$4, MATCH(G9, _RiskMatrix!$A$2:$A$4, 0), MATCH(H9, _RiskMatrix!$B$1:$D$1, 0) )) -> Vysoká | J9: =IF(I9="", "", I9) -> Vysoká | K9: Statické heslo | L9: 1. Zavedení procesu pravidelné rotace hesla. 2. Implementace mTLS (Mutual TLS) pro vzájemné ověřování jednotky a serveru. | M9: Otevřené | N9: 46035
A10: RISK-API-02 | B10: API-01 | C10: =IFERROR(VLOOKUP(B10, 'Asset Register'!A:B, 2, FALSE), "") -> Telemetry Data API (FLT) | D10: Fleet manager | E10: Broken Object Level Authorization (BOLA) | F10: Útočník se přihlásí jako "Zákazník A", ale přes API si řekne o data "Zákazníka B" a systém mu je vydá. | G10: Vysoký | H10: Střední | I10: =IF(OR(G10="", H10=""), "", INDEX(_RiskMatrix!$B$2:$D$4, MATCH(G10, _RiskMatrix!$A$2:$A$4, 0), MATCH(H10, _RiskMatrix!$B$1:$D$1, 0) )) -> Vysoká | J10: =IF(I10="", "", I10) -> Vysoká | K10: Ověření identity uživatele pomocí přihlašovacích údajů (Autentizace). | L10: Implementace kontroly oprávnění na úrovni objektu (Autorizace). Server musí při každém volání API ověřit, zda přihlášený uživatel má vztah k požadovanému ID lokomotivy v databázi. | M10: Řeší se | N10: 46035
A11: RISK-BACK-01 | B11: SYS-BACK-01 | C11: =IFERROR(VLOOKUP(B11, 'Asset Register'!A:B, 2, FALSE), "") -> Backend infrastruktura | D11: Fleet manager | E11: Závislost na dodavateli backend serveru. | F11: Ztráta kontroly nad fyzickou bezpečností a dostupností dat. | G11: Vysoký | H11: Nízká | I11: =IF(OR(G11="", H11=""), "", INDEX(_RiskMatrix!$B$2:$D$4, MATCH(G11, _RiskMatrix!$A$2:$A$4, 0), MATCH(H11, _RiskMatrix!$B$1:$D$1, 0) )) -> Střední | J11: =IF(I11="", "", I11) -> Střední | K11: SLA s dodavatelem | L11: Prověřit existenci Exit strategie (jak dostaneme naše data k sobě, kdyby dodavatel skončil) a zkontrolovat platnost SLA. | M11: Akceptované | N11: 46035
A12: RISK-BACK-02 | B12: SYS-BACK-02 | C12: =IFERROR(VLOOKUP(B12, 'Asset Register'!A:B, 2, FALSE), "") -> Záložní backend infrastruktura | D12: Fleet manager | E12: Propagace logické chyby | F12: Pokud dojde k logickému poškození dat (např. chyba v databázovém skriptu, lidský omyl při mazání nebo zašifrování ransomwarem), tato chyba se okamžitě přenese z hlavního serveru na záložní. Výsledkem jsou dvě identické kopie nepoužitelných dat. | G12: Vysoký | H12: Nízká | I12: =IF(OR(G12="", H12=""), "", INDEX(_RiskMatrix!$B$2:$D$4, MATCH(G12, _RiskMatrix!$A$2:$A$4, 0), MATCH(H12, _RiskMatrix!$B$1:$D$1, 0) )) -> Střední | J12: =IF(I12="", "", I12) -> Střední | K12: Real-time replikace dat na horkou zálohu (Hot Standby). | L12: Implementovat "Studenou zálohu" (Offline/Immutable backup) – např. jednou denně snímek dat, na který nelze ze serveru sahat/mazat. | M12: Otevřené | N12: 46035
A13: RISK-NET-03 | B13: NET-VPN-01 | C13: =IFERROR(VLOOKUP(B13, 'Asset Register'!A:B, 2, FALSE), "") -> Správcovský přístup k backend inrastruktuře | D13: Fleet manager | E13: Zneužití VPN přístupu | F13: Útočník získá přístupové údaje do VPN (phishingem, krádeží notebooku nebo odposlechem hesla). Vzhledem k absenci druhého faktoru (MFA) se může přihlásit do infrastruktury jako legitimní správce a získat plnou kontrolu nad backendem. | G13: Vysoký | H13: Střední | I13: =IF(OR(G13="", H13=""), "", INDEX(_RiskMatrix!$B$2:$D$4, MATCH(G13, _RiskMatrix!$A$2:$A$4, 0), MATCH(H13, _RiskMatrix!$B$1:$D$1, 0) )) -> Vysoká | J13: =IF(I13="", "", I13) -> Vysoká | K13: Přístup přes VPN chráněný statickým uživatelským jménem a heslem. | L13: Povinné zavedení MFA/2FA (např. mobilní autentizátor) pro všechny administrátorské přístupy přes VPN. | M13: Řeší se | N13: 46035
... A20: RISK-IRM-02 | B20: PROC-IRM-01 | C20: =IFERROR(VLOOKUP(B20, 'Asset Register'!A:B, 2, FALSE), "") -> Incident Response Process | D20: Fleet manager | E20: Nedostatečné logování aktivit (Lack of Logging) | F20: Systém neukládá dostatečné detaily o přístupech k API a aktivitách adminů ve VPN. Při incidentu nelze zpětně dohledat, co útočník ukradl nebo změnil. | G20: Vysoký | H20: Vysoká | I20: =IF(OR(G20="", H20=""), "", INDEX(_RiskMatrix!$B$2:$D$4, MATCH(G20, _RiskMatrix!$A$2:$A$4, 0), MATCH(H20, _RiskMatrix!$B$1:$D$1, 0) )) -> Vysoká | J20: =IF(I20="", "", I20) -> Vysoká | K20: Logování pouze základních systémových chyb a času přihlášení do VPN. | L20: Zavést Centralizované logování (např. SIEM nebo ELK stack). Logovat každý úspěšný/neúspěšný přístup k API včetně ID objektu (lokomotivy), ke kterému se přistupovalo. | M20: Řeší se | N20: 46036
C21: =IFERROR(VLOOKUP(B21, 'Asset Register'!A:B, 2, FALSE), "") | I21: =IF(OR(G21="", H21=""), "", INDEX(_RiskMatrix!$B$2:$D$4, MATCH(G21, _RiskMatrix!$A$2:$A$4, 0), MATCH(H21, _RiskMatrix!$B$1:$D$1, 0) )) | J21: =IF(I21="", "", I21)
C22: =IFERROR(VLOOKUP(B22, 'Asset Register'!A:B, 2, FALSE), "") | I22: =IF(OR(G22="", H22=""), "", INDEX(_RiskMatrix!$B$2:$D$4, MATCH(G22, _RiskMatrix!$A$2:$A$4, 0), MATCH(H22, _RiskMatrix!$B$1:$D$1, 0) )) | J22: =IF(I22="", "", I22)
C23: =IFERROR(VLOOKUP(B23, 'Asset Register'!A:B, 2, FALSE), "") | I23: =IF(OR(G23="", H23=""), "", INDEX(_RiskMatrix!$B$2:$D$4, MATCH(G23, _RiskMatrix!$A$2:$A$4, 0), MATCH(H23, _RiskMatrix!$B$1:$D$1, 0) )) | J23: =IF(I23="", "", I23)
C24: =IFERROR(VLOOKUP(B24, 'Asset Register'!A:B, 2, FALSE), "") | I24: =IF(OR(G24="", H24=""), "", INDEX(_RiskMatrix!$B$2:$D$4, MATCH(G24, _RiskMatrix!$A$2:$A$4, 0), MATCH(H24, _RiskMatrix!$B$1:$D$1, 0) )) | J24: =IF(I24="", "", I24)
C25: =IFERROR(VLOOKUP(B25, 'Asset Register'!A:B, 2, FALSE), "") | I25: =IF(OR(G25="", H25=""), "", INDEX(_RiskMatrix!$B$2:$D$4, MATCH(G25, _RiskMatrix!$A$2:$A$4, 0), MATCH(H25, _RiskMatrix!$B$1:$D$1, 0) )) | J25: =IF(I25="", "", I25)
C26: =IFERROR(VLOOKUP(B26, 'Asset Register'!A:B, 2, FALSE), "") | I26: =IF(OR(G26="", H26=""), "", INDEX(_RiskMatrix!$B$2:$D$4, MATCH(G26, _RiskMatrix!$A$2:$A$4, 0), MATCH(H26, _RiskMatrix!$B$1:$D$1, 0) )) | J26: =IF(I26="", "", I26)
C27: =IFERROR(VLOOKUP(B27, 'Asset Register'!A:B, 2, FALSE), "") | J27: =IF(I27="", "", I27)
C28: =IFERROR(VLOOKUP(B28, 'Asset Register'!A:B, 2, FALSE), "") | I28: =IF(OR(G28="", H28=""), "", INDEX(_RiskMatrix!$B$2:$D$4, MATCH(G28, _RiskMatrix!$A$2:$A$4, 0), MATCH(H28, _RiskMatrix!$B$1:$D$1, 0) )) | J28: =IF(I28="", "", I28)
C29: =IFERROR(VLOOKUP(B29, 'Asset Register'!A:B, 2, FALSE), "") | I29: =IF(OR(G29="", H29=""), "", INDEX(_RiskMatrix!$B$2:$D$4, MATCH(G29, _RiskMatrix!$A$2:$A$4, 0), MATCH(H29, _RiskMatrix!$B$1:$D$1, 0) )) | J29: =IF(I29="", "", I29)
C30: =IFERROR(VLOOKUP(B30, 'Asset Register'!A:B, 2, FALSE), "") | I30: =IF(OR(G30="", H30=""), "", INDEX(_RiskMatrix!$B$2:$D$4, MATCH(G30, _RiskMatrix!$A$2:$A$4, 0), MATCH(H30, _RiskMatrix!$B$1:$D$1, 0) )) | J30: =IF(I30="", "", I30)
C31: =IFERROR(VLOOKUP(B31, 'Asset Register'!A:B, 2, FALSE), "") | I31: =IF(OR(G31="", H31=""), "", INDEX(_RiskMatrix!$B$2:$D$4, MATCH(G31, _RiskMatrix!$A$2:$A$4, 0), MATCH(H31, _RiskMatrix!$B$1:$D$1, 0) )) | J31: =IF(I31="", "", I31)
C32: =IFERROR(VLOOKUP(B32, 'Asset Register'!A:B, 2, FALSE), "") | I32: =IF(OR(G32="", H32=""), "", INDEX(_RiskMatrix!$B$2:$D$4, MATCH(G32, _RiskMatrix!$A$2:$A$4, 0), MATCH(H32, _RiskMatrix!$B$1:$D$1, 0) )) | J32: =IF(I32="", "", I32)
C33: =IFERROR(VLOOKUP(B33, 'Asset Register'!A:B, 2, FALSE), "") | I33: =IF(OR(G33="", H33=""), "", INDEX(_RiskMatrix!$B$2:$D$4, MATCH(G33, _RiskMatrix!$A$2:$A$4, 0), MATCH(H33, _RiskMatrix!$B$1:$D$1, 0) )) | J33: =IF(I33="", "", I33)
C34: =IFERROR(VLOOKUP(B34, 'Asset Register'!A:B, 2, FALSE), "") | I34: =IF(OR(G34="", H34=""), "", INDEX(_RiskMatrix!$B$2:$D$4, MATCH(G34, _RiskMatrix!$A$2:$A$4, 0), MATCH(H34, _RiskMatrix!$B$1:$D$1, 0) )) | J34: =IF(I34="", "", I34)
C35: =IFERROR(VLOOKUP(B35, 'Asset Register'!A:B, 2, FALSE), "") | I35: =IF(OR(G35="", H35=""), "", INDEX(_RiskMatrix!$B$2:$D$4, MATCH(G35, _RiskMatrix!$A$2:$A$4, 0), MATCH(H35, _RiskMatrix!$B$1:$D$1, 0) )) | J35: =IF(I35="", "", I35)
C36: =IFERROR(VLOOKUP(B36, 'Asset Register'!A:B, 2, FALSE), "") | I36: =IF(OR(G36="", H36=""), "", INDEX(_RiskMatrix!$B$2:$D$4, MATCH(G36, _RiskMatrix!$A$2:$A$4, 0), MATCH(H36, _RiskMatrix!$B$1:$D$1, 0) )) | J36: =IF(I36="", "", I36)
C37: =IFERROR(VLOOKUP(B37, 'Asset Register'!A:B, 2, FALSE), "") | I37: =IF(OR(G37="", H37=""), "", INDEX(_RiskMatrix!$B$2:$D$4, MATCH(G37, _RiskMatrix!$A$2:$A$4, 0), MATCH(H37, _RiskMatrix!$B$1:$D$1, 0) )) | J37: =IF(I37="", "", I37)
C38: =IFERROR(VLOOKUP(B38, 'Asset Register'!A:B, 2, FALSE), "") | I38: =IF(OR(G38="", H38=""), "", INDEX(_RiskMatrix!$B$2:$D$4, MATCH(G38, _RiskMatrix!$A$2:$A$4, 0), MATCH(H38, _RiskMatrix!$B$1:$D$1, 0) )) | J38: =IF(I38="", "", I38)
C39: =IFERROR(VLOOKUP(B39, 'Asset Register'!A:B, 2, FALSE), "") | I39: =IF(OR(G39="", H39=""), "", INDEX(_RiskMatrix!$B$2:$D$4, MATCH(G39, _RiskMatrix!$A$2:$A$4, 0), MATCH(H39, _RiskMatrix!$B$1:$D$1, 0) )) | J39: =IF(I39="", "", I39)
... C301: =IFERROR(VLOOKUP(B301, 'Asset Register'!A:B, 2, FALSE), "") | I301: =IF(OR(G301="", H301=""), "", INDEX(_RiskMatrix!$B$2:$D$4, MATCH(G301, _RiskMatrix!$A$2:$A$4, 0), MATCH(H301, _RiskMatrix!$B$1:$D$1, 0) )) | J301: =IF(I301="", "", I301)

Sheet Instrukce-AR
A1: Instrukce – Asset Register
A3: Účel
A4: Tento Asset Register slouží k evidenci IT / OT / IoT aktiv a základnímu přehledu o jejich:
A5: umístění
A6: odpovědnosti
A7: provozním stavu
A8: bezpečnostní kritičnosti
A9: Je navržen jako jednoduchý, přehledný základ, vhodný pro malé a střední organizace.
A11: Zásady vyplňování
A12: Každý řádek = jedno aktivum
A13: Používejte hodnoty z rozevíracích seznamů (číselníků), pokud jsou k dispozici.
A14: Nepřepisujte číselníky, pokud k tomu nemáte důvod
... A60: Důvěrnosti
A61: Hodnoty: | B61: Nízká | C61: Střední | D61: Vysoká
A63: Dostupnost
A64: Jak důležité je, aby bylo aktivum dostupné.
A66: Integrita
A67: Jak závažný by byl dopad při změně nebo poškození dat.
A69: Důvěrnost
A70: Jak citlivá jsou data zpracovávaná aktivem.
A72: Síť
A73: Síťové zařazení aktiva:
A74: LAN / OT / Internet / Offline
A76: Přístup
A77: Způsob přístupu k aktivu:
A78: Lokální
... A168: Asset register zůstává plně funkční i bez použití barev.

Sheet Instrukce-RR
A1: Instrukce – Asset Register
A3: Účel
A4: Risk Register slouží k evidenci a řízení bezpečnostních rizik vztahujících se k IT / OT / IoT aktivům.
A5: Umožňuje:
A6: identifikovat rizika navázaná na konkrétní aktiva
A7: vyhodnotit jejich dopad a pravděpodobnost
A8: stanovit prioritu řešení
A9: sledovat stav a odpovědnost za riziko
A10: Je navržen jako jednoduchý a praktický nástroj vhodný pro malé a střední organizace.
A12: Zásady vyplňování
A13: Každý řádek = jedno riziko
A14: Rizika se zapisují pouze pro relevantní aktiva (ne všechna aktiva musí mít riziko)
... A121: Použití barev je nepovinné a nemá vliv na význam dat.

Sheet Legenda_AR
A1: Sloupec | B1: Hodnota | C1: Význam / Definice
A2: Typ aktiva | B2: IT | C2: Informační technologie (kancelářská technika, servery)
B3: OT | C3: Provozní technologie (výrobní stroje, řídicí systémy)
B4: IoT | C4: Internet věcí (chytrá čidla, kamery, IP senzory)
A5: Kategorie | B5: Aplikace | C5: Fyzický server nebo virtuální instance
B6: Databáze | C6: Databázové systémy
B7: Dataset / Data | C7: Strukturované soubory dat
B8: PLC | C8: Řídicí jednotky výrobních linek
B9: Politika / Governance | C9: Pravidla a standardy řízení
B10: Pracovní stanice | C10: Koncový počítač uživatele
B11: Proces | C11: Sled činností k dosažení cíle
B12: Security Object (certifikáty, klíče) | C12: Certifikáty a šifrovací klíče
B13: Senzor / Device | C13: Senzory a měřicí zařízení
B14: Server | C14: Fyzický server nebo virtuální instance
B15: Síťová služba | C15: Komunikační služby a protokoly
B16: Síťové zařízení | C16: Routery, switche a firewally
B17: Software / Firmware | C17: Programové vybavení a firmware
B18: Ostatní | C18: Jiná zařízení nebo infrastruktura
A19: Oddělení | B19: IT | C19: Správa a provoz IT aktiv
B20: Provoz | C20: Provozní technologie
B21: Údržba | C21: Údržba a servis
B22: Externí dodavatel | C22: Aktivum spravované externě
A23: Stav aktiva | B23: V provozu | C23: Aktivum je zapojené, funkční a aktivně se používá
B24: Mimo provoz | C24: Dočasně neaktivní (např. v záloze nebo čeká na nasazení)
B25: V servisu | C25: Probíhá oprava, údržba nebo konfigurace
B26: Vyřazeno | C26: Trvale vyřazeno; záznam zůstává pro potřeby auditu
A27: Kritičnost (CIA) | B27: Nízká | C27: Dopad incidentu je zanedbatelný, neohrožuje chod firmy
B28: Střední | C28: Omezení služeb, dopad na efektivitu, proces běží dál
B29: Vysoká | C29: Kritický dopad, zastavení výroby nebo únik citlivých dat
A30: Dostupnost | B30: Nízká / Střední / Vysoká | C30: Hodnocení, jak důležité je, aby aktivum bylo dostupné
A31: Integrita | B31: Nízká / Střední / Vysoká | C31: Hodnocení dopadu poškození dat nebo konfigurace
A32: Důvěrnost | B32: Nízká / Střední / Vysoká | C32: Hodnocení citlivosti dat zpracovávaných aktivem
A33: Síť | B33: LAN | C33: Připojeno do lokální sítě
B34: OT | C34: Připojeno do provozní sítě
B35: Internet | C35: Přístup přes veřejný internet
B36: Offline | C36: Žádné síťové připojení
A37: Přístup | B37: Lokální | C37: Nutná fyzická přítomnost u zařízení
B38: Remote | C38: Vzdálený přístup v rámci sítě
B39: VPN | C39: Bezpečný šifrovaný přístup
B40: Žádný | C40: Žádný přístup ani lokální, ani vzdálený
...

Sheet Legenda_RR
A1: Sloupec | B1: Hodnota | C1: Význam / Definice
A2: Risk ID | B2: – | C2: Jednoznačný identifikátor rizika
A3: Asset ID | B3: – | C3: Odkaz na aktivum z Asset Registeru
A4: Název aktiva | B4: – | C4: Automaticky doplněný název aktiva dle Asset ID
A5: Název rizika | B5: – | C5: Krátký výstižný název rizika
A6: Vlastník rizika | C6: Role odpovědná za řízení rizika
A7: Popis rizika | B7: – | C7: Stručný popis scénáře rizika
A8: Dopad | B8: Nízký | C8: Omezený dopad na provoz
B9: Střední | C9: Částečné omezení služeb
B10: Vysoký | C10: Kritický dopad
A11: Pravděpodobnost | B11: Nízká | C11: Výskyt rizika je nepravděpodobný
B12: Střední | C12: Riziko se může vyskytnout
B13: Vysoká | C13: Riziko je očekávatelné
A14: Úroveň rizika | B14: Nízká | C14: Automaticky vypočtená úroveň rizika
B15: Střední | C15: Vyžaduje plánování opatření
B16: Vysoká | C16: Vyžaduje bezodkladné řízení
A17: Priorita | B17: Nízká | C17: Řešení v běžném plánování
B18: Střední | C18: Krátkodobý plán řešení
B19: Vysoká | C19: Přednostní řešení
A20: Stávající opatření | B20: – | C20: Existující kontrolní opatření
A21: Doporučené opatření | B21: – | C21: Návrh dalších kroků ke snížení rizika
A22: Stav | B22: Otevřené | C22: Riziko identifikováno
B23: Řeší se | C23: Probíhá řešení
B24: Akceptované | C24: Riziko přijato vedením
B25: Uzavřené | C25: Riziko ošetřeno
A26: Datum revize | B26: – | C26: Datum poslední aktualizace záznamu

Sheet Číselníky-AR
A1: Typ aktiva | B1: Kategorie | C1: Oddělení | D1: StavAktiva | E1: CIA | F1: Síť | G1: Přístup | H1: Zálohování | I1: Aktualizace | J1: TypPoznámky
A2: IT | B2: Aplikace | C2: IT | D2: V provozu | E2: Nízká | F2: LAN | G2: Lokální | H2: Ano | I2: Automatické | J2: Riziko
A3: OT | B3: Databáze | C3: Provoz | D3: Mimo provoz | E3: Střední | F3: OT | G3: Remote | H3: Ne | I3: Ruční | J3: Výjimka
A4: IoT | B4: Dataset / Data | C4: Údržba | D4: V servisu | E4: Vysoká | F4: Internet | G4: VPN | H4: N/A | I4: Není možné | J4: Technický dluh
B5: PLC | C5: Externí dodavatel | D5: Vyřazeno | F5: Offline | G5: Žádný | J5: Provozní omezení
B6: Politika / Governance
B7: Pracovní stanice
B8: Proces
B9: Security Object (certifikáty, klíče)
B10: Senzor / Device
B11: Server
B12: Síťová služba
B13: Síťové zařízení
B14: Software / Firmware
B15: Ostatní

Sheet Číselníky-RR
A1: Riziko | B1: Dopad | C1: Stav
A2: Nízká | B2: Nízký | C2: Otevřené
A3: Střední | B3: Střední | C3: Řeší se
A4: Vysoká | B4: Vysoký | C4: Akceptované
C5: Uzavřené

Sheet _RiskMatrix
A1: Dopad / Pravděpodobnost | B1: Nízká | C1: Střední | D1: Vysoká
A2: Nízký | B2: Nízká | C2: Nízká | D2: Střední
A3: Střední | B3: Nízká | C3: Střední | D3: Vysoká
A4: Vysoký | B4: Střední | C4: Vysoká | D4: Vysoká
